/scratch/cs/imagedb/picsom/databases/vist/conda_vist/lib/python3.6/site-packages/h5py/__init__.py:36: FutureWarning: Conversion of the second argument of issubdtype from `float` to `np.floating` is deprecated. In future, it will be treated as `np.float64 == np.dtype(float).type`.
  from ._conv import register_converters as _register_converters
Using TensorFlow backend.
Traceback (most recent call last):
  File "/scratch/cs/imagedb/picsom/databases/vist/conda_vist/lib/python3.6/site-packages/tensorflow/python/pywrap_tensorflow.py", line 58, in <module>
    from tensorflow.python.pywrap_tensorflow_internal import *
  File "/scratch/cs/imagedb/picsom/databases/vist/conda_vist/lib/python3.6/site-packages/tensorflow/python/pywrap_tensorflow_internal.py", line 28, in <module>
    _pywrap_tensorflow_internal = swig_import_helper()
  File "/scratch/cs/imagedb/picsom/databases/vist/conda_vist/lib/python3.6/site-packages/tensorflow/python/pywrap_tensorflow_internal.py", line 24, in swig_import_helper
    _mod = imp.load_module('_pywrap_tensorflow_internal', fp, pathname, description)
  File "/scratch/cs/imagedb/picsom/databases/vist/conda_vist/lib/python3.6/imp.py", line 243, in load_module
    return load_dynamic(name, filename, file)
  File "/scratch/cs/imagedb/picsom/databases/vist/conda_vist/lib/python3.6/imp.py", line 343, in load_dynamic
    return _load(spec)
ImportError: libcudnn.so.6: cannot open shared object file: No such file or directory

During handling of the above exception, another exception occurred:

Traceback (most recent call last):
  File "inference_model.py", line 1, in <module>
    from keras.optimizers import *
  File "/scratch/cs/imagedb/picsom/databases/vist/conda_vist/lib/python3.6/site-packages/keras/__init__.py", line 3, in <module>
    from . import utils
  File "/scratch/cs/imagedb/picsom/databases/vist/conda_vist/lib/python3.6/site-packages/keras/utils/__init__.py", line 6, in <module>
    from . import conv_utils
  File "/scratch/cs/imagedb/picsom/databases/vist/conda_vist/lib/python3.6/site-packages/keras/utils/conv_utils.py", line 3, in <module>
    from .. import backend as K
  File "/scratch/cs/imagedb/picsom/databases/vist/conda_vist/lib/python3.6/site-packages/keras/backend/__init__.py", line 83, in <module>
    from .tensorflow_backend import *
  File "/scratch/cs/imagedb/picsom/databases/vist/conda_vist/lib/python3.6/site-packages/keras/backend/tensorflow_backend.py", line 1, in <module>
    import tensorflow as tf
  File "/scratch/cs/imagedb/picsom/databases/vist/conda_vist/lib/python3.6/site-packages/tensorflow/__init__.py", line 24, in <module>
    from tensorflow.python import *
  File "/scratch/cs/imagedb/picsom/databases/vist/conda_vist/lib/python3.6/site-packages/tensorflow/python/__init__.py", line 49, in <module>
    from tensorflow.python import pywrap_tensorflow
  File "/scratch/cs/imagedb/picsom/databases/vist/conda_vist/lib/python3.6/site-packages/tensorflow/python/pywrap_tensorflow.py", line 72, in <module>
    raise ImportError(msg)
ImportError: Traceback (most recent call last):
  File "/scratch/cs/imagedb/picsom/databases/vist/conda_vist/lib/python3.6/site-packages/tensorflow/python/pywrap_tensorflow.py", line 58, in <module>
    from tensorflow.python.pywrap_tensorflow_internal import *
  File "/scratch/cs/imagedb/picsom/databases/vist/conda_vist/lib/python3.6/site-packages/tensorflow/python/pywrap_tensorflow_internal.py", line 28, in <module>
    _pywrap_tensorflow_internal = swig_import_helper()
  File "/scratch/cs/imagedb/picsom/databases/vist/conda_vist/lib/python3.6/site-packages/tensorflow/python/pywrap_tensorflow_internal.py", line 24, in swig_import_helper
    _mod = imp.load_module('_pywrap_tensorflow_internal', fp, pathname, description)
  File "/scratch/cs/imagedb/picsom/databases/vist/conda_vist/lib/python3.6/imp.py", line 243, in load_module
    return load_dynamic(name, filename, file)
  File "/scratch/cs/imagedb/picsom/databases/vist/conda_vist/lib/python3.6/imp.py", line 343, in load_dynamic
    return _load(spec)
ImportError: libcudnn.so.6: cannot open shared object file: No such file or directory


Failed to load the native TensorFlow runtime.

See https://www.tensorflow.org/install/install_sources#common_installation_problems

for some common reasons and solutions.  Include the entire stack trace
above this error message when asking for help.
perl: warning: Setting locale failed.
perl: warning: Please check that your locale settings:
	LANGUAGE = (unset),
	LC_ALL = (unset),
	LC_CTYPE = "UTF-8",
	LANG = "en_GB.UTF-8"
    are supported and installed on your system.
perl: warning: Falling back to the standard locale ("C").
srun: error: gpu22: task 0: Exited with exit code 1
srun: Terminating job step 32939416.0
stories generated for val dataset
perl: warning: Setting locale failed.
perl: warning: Please check that your locale settings:
	LANGUAGE = (unset),
	LC_ALL = (unset),
	LC_CTYPE = "UTF-8",
	LANG = "en_GB.UTF-8"
    are supported and installed on your system.
perl: warning: Falling back to the standard locale ("C").
