Thu 14 Jun 00:55:03 EEST 2018
Traceback (most recent call last):
  File "/scratch/cs/imagedb/picsom/databases/vist/conda_vist/lib/python3.6/site-packages/tensorflow/python/pywrap_tensorflow.py", line 58, in <module>
    from tensorflow.python.pywrap_tensorflow_internal import *
  File "/scratch/cs/imagedb/picsom/databases/vist/conda_vist/lib/python3.6/site-packages/tensorflow/python/pywrap_tensorflow_internal.py", line 28, in <module>
    _pywrap_tensorflow_internal = swig_import_helper()
  File "/scratch/cs/imagedb/picsom/databases/vist/conda_vist/lib/python3.6/site-packages/tensorflow/python/pywrap_tensorflow_internal.py", line 24, in swig_import_helper
    _mod = imp.load_module('_pywrap_tensorflow_internal', fp, pathname, description)
  File "/scratch/cs/imagedb/picsom/databases/vist/conda_vist/lib/python3.6/imp.py", line 243, in load_module
    return load_dynamic(name, filename, file)
  File "/scratch/cs/imagedb/picsom/databases/vist/conda_vist/lib/python3.6/imp.py", line 343, in load_dynamic
    return _load(spec)
ImportError: libcuda.so.1: cannot open shared object file: No such file or directory

During handling of the above exception, another exception occurred:

Traceback (most recent call last):
  File "dataset/models/alexnet/myalexnet_forward_newtf.py", line 22, in <module>
    import tensorflow as tf
  File "/scratch/cs/imagedb/picsom/databases/vist/conda_vist/lib/python3.6/site-packages/tensorflow/__init__.py", line 24, in <module>
    from tensorflow.python import *
  File "/scratch/cs/imagedb/picsom/databases/vist/conda_vist/lib/python3.6/site-packages/tensorflow/python/__init__.py", line 49, in <module>
    from tensorflow.python import pywrap_tensorflow
  File "/scratch/cs/imagedb/picsom/databases/vist/conda_vist/lib/python3.6/site-packages/tensorflow/python/pywrap_tensorflow.py", line 72, in <module>
    raise ImportError(msg)
ImportError: Traceback (most recent call last):
  File "/scratch/cs/imagedb/picsom/databases/vist/conda_vist/lib/python3.6/site-packages/tensorflow/python/pywrap_tensorflow.py", line 58, in <module>
    from tensorflow.python.pywrap_tensorflow_internal import *
  File "/scratch/cs/imagedb/picsom/databases/vist/conda_vist/lib/python3.6/site-packages/tensorflow/python/pywrap_tensorflow_internal.py", line 28, in <module>
    _pywrap_tensorflow_internal = swig_import_helper()
  File "/scratch/cs/imagedb/picsom/databases/vist/conda_vist/lib/python3.6/site-packages/tensorflow/python/pywrap_tensorflow_internal.py", line 24, in swig_import_helper
    _mod = imp.load_module('_pywrap_tensorflow_internal', fp, pathname, description)
  File "/scratch/cs/imagedb/picsom/databases/vist/conda_vist/lib/python3.6/imp.py", line 243, in load_module
    return load_dynamic(name, filename, file)
  File "/scratch/cs/imagedb/picsom/databases/vist/conda_vist/lib/python3.6/imp.py", line 343, in load_dynamic
    return _load(spec)
ImportError: libcuda.so.1: cannot open shared object file: No such file or directory


Failed to load the native TensorFlow runtime.

See https://www.tensorflow.org/install/install_sources#common_installation_problems

for some common reasons and solutions.  Include the entire stack trace
above this error message when asking for help.
srun: error: pe82: task 0: Exited with exit code 1
srun: Terminating job step 32622071.0
something broke
Thu 14 Jun 00:55:07 EEST 2018
